Workbook

Sheet AHORROS
A1: ID | B1: GRUPO | C1: # | D1: FECHA DEPOSITO | E1: DEPOSITO | F1: PAGO | G1: AHORRO | H1: AHORRO ACUMULADO | I1: % AHORRO
A2: 000001 | B2: BRILLANTES | C2: 1 | D2: 45880 | E2: 10863 | F2: 10336.09 | G2: =E2-F2 -> 526.91 | H2: =G2 -> 526.91 | I2: =G2/F2 -> 0.050977691
A3: 000001 | B3: BRILLANTES | C3: 2 | D3: 45887 | E3: 10863 | F3: 10336.09 | G3: =E3-F3 -> 526.91 | H3: =H2+G3 -> 1053.82 | I3: =G3/F3 -> 0.050977691
A4: 000001 | B4: BRILLANTES | C4: 3 | D4: 45894 | E4: 10863 | F4: 10336.09 | G4: =E4-F4 -> 526.91 | H4: =H3+G4 -> 1580.73 | I4: =G4/F4 -> 0.050977691
A5: 000001 | B5: BRILLANTES | C5: 4 | D5: 45901 | E5: 10863 | F5: 10336.09 | G5: =E5-F5 -> 526.91 | H5: =H4+G5 -> 2107.64 | I5: =G5/F5 -> 0.050977691
A6: 000001 | B6: BRILLANTES | C6: 5 | D6: 45908 | E6: 10863 | F6: 10336.09 | G6: =E6-F6 -> 526.91 | H6: =H5+G6 -> 2634.55 | I6: =G6/F6 -> 0.050977691
A7: 000001 | B7: BRILLANTES | C7: 6 | D7: 45914 | E7: 10863 | F7: 10336.09 | G7: =E7-F7 -> 526.91 | H7: =H6+G7 -> 3161.46 | I7: =G7/F7 -> 0.050977691
A8: 000001 | B8: BRILLANTES | C8: 7 | D8: 45924 | E8: 11244 | F8: 10336.09 | G8: =E8-F8 -> 907.91 | H8: =H7+G8 -> 4069.37 | I8: =G8/F8 -> 0.087838825
A9: 000001 | B9: BRILLANTES | C9: 8 | G9: =E9-F9 -> 0 | H9: =H8+G9 -> 4069.37
A10: 000001 | B10: BRILLANTES | C10: 9 | G10: =E10-F10 -> 0 | H10: =H9+G10 -> 4069.37
A11: 000001 | B11: BRILLANTES | C11: 10 | G11: =E11-F11 -> 0 | H11: =H10+G11 -> 4069.37
A12: 000001 | B12: BRILLANTES | C12: 11 | G12: =E12-F12 -> 0 | H12: =H11+G12 -> 4069.37
A13: 000001 | B13: BRILLANTES | C13: 12 | G13: =E13-F13 -> 0 | H13: =H12+G13 -> 4069.37
A14: 000001 | B14: BRILLANTES | C14: 13 | G14: =E14-F14 -> 0 | H14: =H13+G14 -> 4069.37
A15: 000001 | B15: BRILLANTES | C15: 14 | G15: =E15-F15 -> 0 | H15: =H14+G15 -> 4069.37
A16: 000001 | B16: BRILLANTES | C16: 15 | G16: =E16-F16 -> 0 | H16: =H15+G16 -> 4069.37
A17: 000001 | B17: BRILLANTES | C17: 16 | G17: =E17-F17 -> 0 | H17: =H16+G17 -> 4069.37
A18: 000002 | B18: MOTIVADORAS | C18: 1 | D18: 45881 | E18: 15730 | F18: 14288.13 | G18: =E18-F18 -> 1441.87 | H18: =G18 -> 1441.87 | I18: =G18/F18 -> 0.10091384
A19: 000002 | B19: MOTIVADORAS | C19: 2 | D19: 45888 | E19: 15730 | F19: 14288.13 | G19: =E19-F19 -> 1441.87 | H19: =H18+G19 -> 2883.74 | I19: =G19/F19 -> 0.10091384
A20: 000002 | B20: MOTIVADORAS | C20: 3 | D20: 45895 | E20: 15730 | F20: 14288.13 | G20: =E20-F20 -> 1441.87 | H20: =H19+G20 -> 4325.61 | I20: =G20/F20 -> 0.10091384
A21: 000002 | B21: MOTIVADORAS | C21: 4 | D21: 45902 | E21: 15729 | F21: 14288.13 | G21: =E21-F21 -> 1440.87 | H21: =H20+G21 -> 5766.48 | I21: =G21/F21 -> 0.10084385
A22: 000002 | B22: MOTIVADORAS | C22: 5 | D22: 45909 | E22: 15729 | F22: 14288.13 | G22: =E22-F22 -> 1440.87 | H22: =H21+G22 -> 7207.35 | I22: =G22/F22 -> 0.10084385
A23: 000002 | B23: MOTIVADORAS | C23: 6 | D23: 45915 | E23: 15730 | F23: 14288.13 | G23: =E23-F23 -> 1441.87 | H23: =H22+G23 -> 8649.22 | I23: =G23/F23 -> 0.10091384
A24: 000002 | B24: MOTIVADORAS | C24: 7 | D24: 45923 | E24: 15730 | F24: 14288.13 | G24: =E24-F24 -> 1441.87 | H24: =H23+G24 -> 10091.09 | I24: =G24/F24 -> 0.10091384
A25: 000002 | B25: MOTIVADORAS | C25: 8 | G25: =E25-F25 -> 0 | H25: =H24+G25 -> 10091.09
A26: 000002 | B26: MOTIVADORAS | C26: 9 | G26: =E26-F26 -> 0 | H26: =H25+G26 -> 10091.09
A27: 000002 | B27: MOTIVADORAS | C27: 10 | G27: =E27-F27 -> 0 | H27: =H26+G27 -> 10091.09
A28: 000002 | B28: MOTIVADORAS | C28: 11 | G28: =E28-F28 -> 0 | H28: =H27+G28 -> 10091.09
A29: 000002 | B29: MOTIVADORAS | C29: 12 | G29: =E29-F29 -> 0 | H29: =H28+G29 -> 10091.09
A30: 000002 | B30: MOTIVADORAS | C30: 13 | G30: =E30-F30 -> 0 | H30: =H29+G30 -> 10091.09
A31: 000002 | B31: MOTIVADORAS | C31: 14 | G31: =E31-F31 -> 0 | H31: =H30+G31 -> 10091.09
A32: 000002 | B32: MOTIVADORAS | C32: 15 | G32: =E32-F32 -> 0 | H32: =H31+G32 -> 10091.09
A33: 000002 | B33: MOTIVADORAS | C33: 16 | G33: =E33-F33 -> 0 | H33: =H32+G33 -> 10091.09
A34: 000003 | B34: ACEITUNAS DE COCKTAIL | C34: 1 | D34: 45884 | E34: 12020 | F34: 11400.1 | G34: =E34-F34 -> 619.9 | H34: =G34 -> 619.9 | I34: =G34/F34 -> 0.054376716
A35: 000003 | B35: ACEITUNAS DE COCKTAIL | C35: 2 | D35: 45891 | E35: 12020 | F35: 11400.1 | G35: =E35-F35 -> 619.9 | H35: =H34+G35 -> 1239.8 | I35: =G35/F35 -> 0.054376716
A36: 000003 | B36: ACEITUNAS DE COCKTAIL | C36: 3 | D36: 45898 | E36: 12000 | F36: 11401 | G36: =E36-F36 -> 599 | H36: =H35+G36 -> 1838.8 | I36: =G36/F36 -> 0.052539251
A37: 000003 | B37: ACEITUNAS DE COCKTAIL | C37: 4 | D37: 45905 | E37: 11940 | F37: 11400 | G37: =E37-F37 -> 540 | H37: =H36+G37 -> 2378.8 | I37: =G37/F37 -> 0.047368421
A38: 000003 | B38: ACEITUNAS DE COCKTAIL | C38: 5 | D38: 45912 | E38: 11860 | F38: 11400 | G38: =E38-F38 -> 460 | H38: =H37+G38 -> 2838.8 | I38: =G38/F38 -> 0.040350877
A39: 000003 | B39: ACEITUNAS DE COCKTAIL | C39: 6 | D39: 45919 | E39: 11860 | F39: 11400 | G39: =E39-F39 -> 460 | H39: =H38+G39 -> 3298.8 | I39: =G39/F39 -> 0.040350877
A40: 000003 | B40: ACEITUNAS DE COCKTAIL | C40: 7 | D40: 45926 | E40: 11970 | F40: 11400 | G40: =E40-F40 -> 570 | H40: =H39+G40 -> 3868.8 | I40: =G40/F40 -> 0.05
...

Sheet ACUMULADO
A1: ID | B1: GRUPO | C1: AHORRO ACUMULADO
A2: 000001 | B2: BRILLANTES | C2: =AHORROS!H17 -> 4069.37
A3: 000002 | B3: MOTIVADORAS | C3: =AHORROS!H33 -> 10091.09
A4: 000003 | B4: ACEITUNAS DE COCKTAIL | C4: =AHORROS!H49 -> 3868.8
A5: 000004 | B5: ORQUIDEAS | C5: =AHORROS!H65 -> 6843.62
A6: 000005 | B6: TUTTY FRATELLY | C6: =AHORROS!H81 -> 8255.8
A7: 000006 | B7: LINDAS | C7: =AHORROS!H97 -> 5053.76
A8: 000007 | B8: NUEVO COMIENZO | C8: =AHORROS!H113 -> 7601.8
A9: 000008 | B9: LIDERES UNIDOS | C9: =AHORROS!H129 -> 5311.84
A10: 000009 | B10: ESPERANZA | C10: =AHORROS!H145 -> 965.9
A11: 000010 | B11: FRESITAS | C11: =AHORROS!H161 -> 2777.82
A12: 000011 | B12: ECHEGUREN | C12: =AHORROS!H177 -> 1456.76
A13: 000012 | B13: ESTRELLA | C13: =AHORROS!H193 -> 3816.82
A14: 000013 | B14: SAN PEDRO | C14: =AHORROS!H209 -> 5177.78
A15: 000015 | B15: GLADIOLAS | C15: =AHORROS!H225 -> 1526.96
A16: 000016 | B16: MARGARITAS | C16: =AHORROS!H241 -> 1614.93
A17: 000017 | B17: XOLOC | C17: =AHORROS!H257 -> 1859.95
A18: 000018 | B18: CRISTAL | C18: =AHORROS!H273 -> 2134
A19: 000020 | B19: CERECITAS | C19: =AHORROS!H289 -> 3469.4
A20: 000022 | B20: HACHI | C20: =AHORROS!H305 -> 2537.92
A21: 000025 | B21: EXITOSAS DE SAN JUAN | C21: =AHORROS!H321 -> 1619.85
A22: 000026 | B22: ANDROMEDA | C22: =AHORROS!H337 -> 1850
A23: 000028 | B23: CAMPEONAS | C23: =AHORROS!H353 -> 1474
A24: 000029 | B24: MOYSEN | C24: =AHORROS!H369 -> 3760
A25: 000030 | B25: FLORECITAS | C25: =AHORROS!H385 -> 2544.55
A26: 000031 | B26: NUEVA LUZ | C26: =AHORROS!H401 -> 1540
A27: 000032 | B27: LOS EFECTIVOS | C27: =AHORROS!H417 -> 6558
A28: 000033 | B28: CUPIDO | C28: =AHORROS!H433 -> 1788
A29: 000034 | B29: SONRISA | C29: =AHORROS!H449 -> 2521
A30: 000035 | B30: 2 DE ABRIL | C30: =AHORROS!H465 -> 2382
A31: 000036 | B31: GARDENIAS | C31: =AHORROS!H481 -> 2955.56
A32: 000037 | B32: FANTASTICAS | C32: =AHORROS!H497 -> 952.84
A33: 000039 | B33: COMETAS | C33: =AHORROS!H513 -> 1876
A34: 000040 | B34: CACHU | C34: =AHORROS!H529 -> 1830
A35: 000041 | B35: PUERTA DE ORO | C35: =AHORROS!H545 -> 19199.32
A36: 000042 | B36: MARIPOSAS | C36: =AHORROS!H561 -> 1198
A37: 000043 | B37: ADELITA | C37: =AHORROS!H577 -> 1200
A38: 000044 | B38: ALAMOS DEL MARISCAL | C38: =AHORROS!H593 -> 1524
A39: 000045 | B39: LEONIDAS 1 | C39: =AHORROS!H609 -> 2219
A40: 000046 | B40: LOS PEQUES | C40: =AHORROS!H625 -> 4256
...
